2018-03-30 13:43:46,724 ERROR: Exception on /reset_password/eyJ0eXAiOiJKV1QiLCJhbGciOiJIUzI1NiJ9.eyJyZXNldF9wYXNzd29yZCI6OCwiZXhwIjoxNTIyNDA3MTkwLjc0MTI0NzR9.dyIGe_SeBSsGAsmVR8dEAUiyZW7vyZ1lrozWMFJ7h-8 [GET] [in /home/dmitry/code/python/Flask/first/venv/lib/python3.6/site-packages/flask/app.py:1560]
Traceback (most recent call last):
  File "/home/dmitry/code/python/Flask/first/venv/lib/python3.6/site-packages/flask/app.py", line 1982, in wsgi_app
    response = self.full_dispatch_request()
  File "/home/dmitry/code/python/Flask/first/venv/lib/python3.6/site-packages/flask/app.py", line 1614, in full_dispatch_request
    rv = self.handle_user_exception(e)
  File "/home/dmitry/code/python/Flask/first/venv/lib/python3.6/site-packages/flask/app.py", line 1517, in handle_user_exception
    reraise(exc_type, exc_value, tb)
  File "/home/dmitry/code/python/Flask/first/venv/lib/python3.6/site-packages/flask/_compat.py", line 33, in reraise
    raise value
  File "/home/dmitry/code/python/Flask/first/venv/lib/python3.6/site-packages/flask/app.py", line 1612, in full_dispatch_request
    rv = self.dispatch_request()
  File "/home/dmitry/code/python/Flask/first/venv/lib/python3.6/site-packages/flask/app.py", line 1598, in dispatch_request
    return self.view_functions[rule.endpoint](**req.view_args)
TypeError: reset_password() got an unexpected keyword argument 'token'
2018-03-30 13:43:48,784 ERROR: Exception on /reset_password/eyJ0eXAiOiJKV1QiLCJhbGciOiJIUzI1NiJ9.eyJyZXNldF9wYXNzd29yZCI6OCwiZXhwIjoxNTIyNDA3MTkwLjc0MTI0NzR9.dyIGe_SeBSsGAsmVR8dEAUiyZW7vyZ1lrozWMFJ7h-8 [GET] [in /home/dmitry/code/python/Flask/first/venv/lib/python3.6/site-packages/flask/app.py:1560]
Traceback (most recent call last):
  File "/home/dmitry/code/python/Flask/first/venv/lib/python3.6/site-packages/flask/app.py", line 1982, in wsgi_app
    response = self.full_dispatch_request()
  File "/home/dmitry/code/python/Flask/first/venv/lib/python3.6/site-packages/flask/app.py", line 1614, in full_dispatch_request
    rv = self.handle_user_exception(e)
  File "/home/dmitry/code/python/Flask/first/venv/lib/python3.6/site-packages/flask/app.py", line 1517, in handle_user_exception
    reraise(exc_type, exc_value, tb)
  File "/home/dmitry/code/python/Flask/first/venv/lib/python3.6/site-packages/flask/_compat.py", line 33, in reraise
    raise value
  File "/home/dmitry/code/python/Flask/first/venv/lib/python3.6/site-packages/flask/app.py", line 1612, in full_dispatch_request
    rv = self.dispatch_request()
  File "/home/dmitry/code/python/Flask/first/venv/lib/python3.6/site-packages/flask/app.py", line 1598, in dispatch_request
    return self.view_functions[rule.endpoint](**req.view_args)
TypeError: reset_password() got an unexpected keyword argument 'token'
2018-03-30 13:43:50,826 ERROR: Exception on /reset_password/eyJ0eXAiOiJKV1QiLCJhbGciOiJIUzI1NiJ9.eyJyZXNldF9wYXNzd29yZCI6OCwiZXhwIjoxNTIyNDA3MTkwLjc0MTI0NzR9.dyIGe_SeBSsGAsmVR8dEAUiyZW7vyZ1lrozWMFJ7h-8 [GET] [in /home/dmitry/code/python/Flask/first/venv/lib/python3.6/site-packages/flask/app.py:1560]
Traceback (most recent call last):
  File "/home/dmitry/code/python/Flask/first/venv/lib/python3.6/site-packages/flask/app.py", line 1982, in wsgi_app
    response = self.full_dispatch_request()
  File "/home/dmitry/code/python/Flask/first/venv/lib/python3.6/site-packages/flask/app.py", line 1614, in full_dispatch_request
    rv = self.handle_user_exception(e)
  File "/home/dmitry/code/python/Flask/first/venv/lib/python3.6/site-packages/flask/app.py", line 1517, in handle_user_exception
    reraise(exc_type, exc_value, tb)
  File "/home/dmitry/code/python/Flask/first/venv/lib/python3.6/site-packages/flask/_compat.py", line 33, in reraise
    raise value
  File "/home/dmitry/code/python/Flask/first/venv/lib/python3.6/site-packages/flask/app.py", line 1612, in full_dispatch_request
    rv = self.dispatch_request()
  File "/home/dmitry/code/python/Flask/first/venv/lib/python3.6/site-packages/flask/app.py", line 1598, in dispatch_request
    return self.view_functions[rule.endpoint](**req.view_args)
TypeError: reset_password() got an unexpected keyword argument 'token'
2018-03-30 14:14:38,538 INFO: Microblog startup [in /home/dmitry/code/python/Flask/first/ap/__init__.py:44]
2018-03-30 14:49:46,811 INFO: Microblog startup [in /home/dmitry/code/python/Flask/first/ap/__init__.py:44]
2018-04-02 15:04:42,119 INFO: Microblog startup [in /home/dmitry/code/python/Flask/first/ap/__init__.py:46]
2018-04-04 12:59:32,573 INFO: Microblog startup [in /home/dmitry/code/python/Flask/first/ap/__init__.py:48]
2018-04-04 17:48:30,640 INFO: Microblog startup [in /home/dmitry/code/python/Flask/first/ap/__init__.py:48]
2018-04-12 13:38:08,607 INFO: Microblog startup [in /home/dmitry/code/python/Flask/first/ap/__init__.py:48]
2018-04-23 15:23:06,365 INFO: Microblog startup [in /home/dmitry/code/python/Flask/first/ap/__init__.py:48]
2018-04-23 15:25:01,221 INFO: Microblog startup [in /home/dmitry/code/python/Flask/first/ap/__init__.py:48]
2018-04-24 10:27:37,585 INFO: Microblog startup [in /home/dmitry/code/python/Flask/first/ap/__init__.py:50]
2018-04-24 11:59:15,677 INFO: Microblog startup [in /home/dmitry/code/python/Flask/first/ap/__init__.py:50]
2018-04-24 12:00:07,580 ERROR: Exception on /index [POST] [in /home/dmitry/code/python/Flask/first/venv/lib/python3.6/site-packages/flask/app.py:1560]
Traceback (most recent call last):
  File "/home/dmitry/code/python/Flask/first/venv/lib/python3.6/site-packages/flask/app.py", line 1982, in wsgi_app
    response = self.full_dispatch_request()
  File "/home/dmitry/code/python/Flask/first/venv/lib/python3.6/site-packages/flask/app.py", line 1614, in full_dispatch_request
    rv = self.handle_user_exception(e)
  File "/home/dmitry/code/python/Flask/first/venv/lib/python3.6/site-packages/flask/app.py", line 1517, in handle_user_exception
    reraise(exc_type, exc_value, tb)
  File "/home/dmitry/code/python/Flask/first/venv/lib/python3.6/site-packages/flask/_compat.py", line 33, in reraise
    raise value
  File "/home/dmitry/code/python/Flask/first/venv/lib/python3.6/site-packages/flask/app.py", line 1612, in full_dispatch_request
    rv = self.dispatch_request()
  File "/home/dmitry/code/python/Flask/first/venv/lib/python3.6/site-packages/flask/app.py", line 1598, in dispatch_request
    return self.view_functions[rule.endpoint](**req.view_args)
  File "/home/dmitry/code/python/Flask/first/venv/lib/python3.6/site-packages/flask_login/utils.py", line 261, in decorated_view
    return func(*args, **kwargs)
  File "/home/dmitry/code/python/Flask/first/ap/routes.py", line 26, in index
    flash(_('It flew away. Suffer!!!'))
  File "/home/dmitry/code/python/Flask/first/venv/lib/python3.6/site-packages/flask_babel/__init__.py", line 552, in gettext
    t = get_translations()
  File "/home/dmitry/code/python/Flask/first/venv/lib/python3.6/site-packages/flask_babel/__init__.py", line 227, in get_translations
    [get_locale()],
  File "/home/dmitry/code/python/Flask/first/venv/lib/python3.6/site-packages/flask_babel/__init__.py", line 261, in get_locale
    locale = Locale.parse(rv)
  File "/home/dmitry/code/python/Flask/first/venv/lib/python3.6/site-packages/babel/core.py", line 268, in parse
    parts = parse_locale(identifier, sep=sep)
  File "/home/dmitry/code/python/Flask/first/venv/lib/python3.6/site-packages/babel/core.py", line 1094, in parse_locale
    raise ValueError('expected only letters, got %r' % lang)
ValueError: expected only letters, got 'en-us'
2018-04-24 12:00:11,749 ERROR: Exception on /index [POST] [in /home/dmitry/code/python/Flask/first/venv/lib/python3.6/site-packages/flask/app.py:1560]
Traceback (most recent call last):
  File "/home/dmitry/code/python/Flask/first/venv/lib/python3.6/site-packages/flask/app.py", line 1982, in wsgi_app
    response = self.full_dispatch_request()
  File "/home/dmitry/code/python/Flask/first/venv/lib/python3.6/site-packages/flask/app.py", line 1614, in full_dispatch_request
    rv = self.handle_user_exception(e)
  File "/home/dmitry/code/python/Flask/first/venv/lib/python3.6/site-packages/flask/app.py", line 1517, in handle_user_exception
    reraise(exc_type, exc_value, tb)
  File "/home/dmitry/code/python/Flask/first/venv/lib/python3.6/site-packages/flask/_compat.py", line 33, in reraise
    raise value
  File "/home/dmitry/code/python/Flask/first/venv/lib/python3.6/site-packages/flask/app.py", line 1612, in full_dispatch_request
    rv = self.dispatch_request()
  File "/home/dmitry/code/python/Flask/first/venv/lib/python3.6/site-packages/flask/app.py", line 1598, in dispatch_request
    return self.view_functions[rule.endpoint](**req.view_args)
  File "/home/dmitry/code/python/Flask/first/venv/lib/python3.6/site-packages/flask_login/utils.py", line 261, in decorated_view
    return func(*args, **kwargs)
  File "/home/dmitry/code/python/Flask/first/ap/routes.py", line 26, in index
    flash(_('It flew away. Suffer!!!'))
  File "/home/dmitry/code/python/Flask/first/venv/lib/python3.6/site-packages/flask_babel/__init__.py", line 552, in gettext
    t = get_translations()
  File "/home/dmitry/code/python/Flask/first/venv/lib/python3.6/site-packages/flask_babel/__init__.py", line 227, in get_translations
    [get_locale()],
  File "/home/dmitry/code/python/Flask/first/venv/lib/python3.6/site-packages/flask_babel/__init__.py", line 261, in get_locale
    locale = Locale.parse(rv)
  File "/home/dmitry/code/python/Flask/first/venv/lib/python3.6/site-packages/babel/core.py", line 268, in parse
    parts = parse_locale(identifier, sep=sep)
  File "/home/dmitry/code/python/Flask/first/venv/lib/python3.6/site-packages/babel/core.py", line 1094, in parse_locale
    raise ValueError('expected only letters, got %r' % lang)
ValueError: expected only letters, got 'en-us'
2018-04-24 12:04:35,022 INFO: Microblog startup [in /home/dmitry/code/python/Flask/first/ap/__init__.py:50]
2018-04-24 12:09:57,721 INFO: Microblog startup [in /home/dmitry/code/python/Flask/first/ap/__init__.py:50]
2018-04-24 12:11:18,894 INFO: Microblog startup [in /home/dmitry/code/python/Flask/first/ap/__init__.py:50]
