2018-03-30 13:30:34,480 ERROR: Exception on /reset_password/eyJ0eXAiOiJKV1QiLCJhbGciOiJIUzI1NiJ9.eyJyZXNldF9wYXNzd29yZCI6OCwiZXhwIjoxNTIyNDA2Mzg1Ljk3ODA4MTV9.2eMoIT3stwq2cGKi0Rf7D06O0qatvIdj9biev5Kc9xY [GET] [in /home/dmitry/code/python/Flask/first/venv/lib/python3.6/site-packages/flask/app.py:1560]
Traceback (most recent call last):
  File "/home/dmitry/code/python/Flask/first/venv/lib/python3.6/site-packages/flask/app.py", line 1982, in wsgi_app
    response = self.full_dispatch_request()
  File "/home/dmitry/code/python/Flask/first/venv/lib/python3.6/site-packages/flask/app.py", line 1614, in full_dispatch_request
    rv = self.handle_user_exception(e)
  File "/home/dmitry/code/python/Flask/first/venv/lib/python3.6/site-packages/flask/app.py", line 1517, in handle_user_exception
    reraise(exc_type, exc_value, tb)
  File "/home/dmitry/code/python/Flask/first/venv/lib/python3.6/site-packages/flask/_compat.py", line 33, in reraise
    raise value
  File "/home/dmitry/code/python/Flask/first/venv/lib/python3.6/site-packages/flask/app.py", line 1612, in full_dispatch_request
    rv = self.dispatch_request()
  File "/home/dmitry/code/python/Flask/first/venv/lib/python3.6/site-packages/flask/app.py", line 1598, in dispatch_request
    return self.view_functions[rule.endpoint](**req.view_args)
TypeError: reset_password() got an unexpected keyword argument 'token'
2018-03-30 13:30:36,278 ERROR: Exception on /reset_password/eyJ0eXAiOiJKV1QiLCJhbGciOiJIUzI1NiJ9.eyJyZXNldF9wYXNzd29yZCI6OCwiZXhwIjoxNTIyNDA2Mzg1Ljk3ODA4MTV9.2eMoIT3stwq2cGKi0Rf7D06O0qatvIdj9biev5Kc9xY [GET] [in /home/dmitry/code/python/Flask/first/venv/lib/python3.6/site-packages/flask/app.py:1560]
Traceback (most recent call last):
  File "/home/dmitry/code/python/Flask/first/venv/lib/python3.6/site-packages/flask/app.py", line 1982, in wsgi_app
    response = self.full_dispatch_request()
  File "/home/dmitry/code/python/Flask/first/venv/lib/python3.6/site-packages/flask/app.py", line 1614, in full_dispatch_request
    rv = self.handle_user_exception(e)
  File "/home/dmitry/code/python/Flask/first/venv/lib/python3.6/site-packages/flask/app.py", line 1517, in handle_user_exception
    reraise(exc_type, exc_value, tb)
  File "/home/dmitry/code/python/Flask/first/venv/lib/python3.6/site-packages/flask/_compat.py", line 33, in reraise
    raise value
  File "/home/dmitry/code/python/Flask/first/venv/lib/python3.6/site-packages/flask/app.py", line 1612, in full_dispatch_request
    rv = self.dispatch_request()
  File "/home/dmitry/code/python/Flask/first/venv/lib/python3.6/site-packages/flask/app.py", line 1598, in dispatch_request
    return self.view_functions[rule.endpoint](**req.view_args)
TypeError: reset_password() got an unexpected keyword argument 'token'
2018-03-30 13:30:38,094 ERROR: Exception on /reset_password/eyJ0eXAiOiJKV1QiLCJhbGciOiJIUzI1NiJ9.eyJyZXNldF9wYXNzd29yZCI6OCwiZXhwIjoxNTIyNDA2Mzg1Ljk3ODA4MTV9.2eMoIT3stwq2cGKi0Rf7D06O0qatvIdj9biev5Kc9xY [GET] [in /home/dmitry/code/python/Flask/first/venv/lib/python3.6/site-packages/flask/app.py:1560]
Traceback (most recent call last):
  File "/home/dmitry/code/python/Flask/first/venv/lib/python3.6/site-packages/flask/app.py", line 1982, in wsgi_app
    response = self.full_dispatch_request()
  File "/home/dmitry/code/python/Flask/first/venv/lib/python3.6/site-packages/flask/app.py", line 1614, in full_dispatch_request
    rv = self.handle_user_exception(e)
  File "/home/dmitry/code/python/Flask/first/venv/lib/python3.6/site-packages/flask/app.py", line 1517, in handle_user_exception
    reraise(exc_type, exc_value, tb)
  File "/home/dmitry/code/python/Flask/first/venv/lib/python3.6/site-packages/flask/_compat.py", line 33, in reraise
    raise value
  File "/home/dmitry/code/python/Flask/first/venv/lib/python3.6/site-packages/flask/app.py", line 1612, in full_dispatch_request
    rv = self.dispatch_request()
  File "/home/dmitry/code/python/Flask/first/venv/lib/python3.6/site-packages/flask/app.py", line 1598, in dispatch_request
    return self.view_functions[rule.endpoint](**req.view_args)
TypeError: reset_password() got an unexpected keyword argument 'token'
2018-03-30 13:30:39,870 ERROR: Exception on /reset_password/eyJ0eXAiOiJKV1QiLCJhbGciOiJIUzI1NiJ9.eyJyZXNldF9wYXNzd29yZCI6OCwiZXhwIjoxNTIyNDA2Mzg1Ljk3ODA4MTV9.2eMoIT3stwq2cGKi0Rf7D06O0qatvIdj9biev5Kc9xY [GET] [in /home/dmitry/code/python/Flask/first/venv/lib/python3.6/site-packages/flask/app.py:1560]
Traceback (most recent call last):
  File "/home/dmitry/code/python/Flask/first/venv/lib/python3.6/site-packages/flask/app.py", line 1982, in wsgi_app
    response = self.full_dispatch_request()
  File "/home/dmitry/code/python/Flask/first/venv/lib/python3.6/site-packages/flask/app.py", line 1614, in full_dispatch_request
    rv = self.handle_user_exception(e)
  File "/home/dmitry/code/python/Flask/first/venv/lib/python3.6/site-packages/flask/app.py", line 1517, in handle_user_exception
    reraise(exc_type, exc_value, tb)
  File "/home/dmitry/code/python/Flask/first/venv/lib/python3.6/site-packages/flask/_compat.py", line 33, in reraise
    raise value
  File "/home/dmitry/code/python/Flask/first/venv/lib/python3.6/site-packages/flask/app.py", line 1612, in full_dispatch_request
    rv = self.dispatch_request()
  File "/home/dmitry/code/python/Flask/first/venv/lib/python3.6/site-packages/flask/app.py", line 1598, in dispatch_request
    return self.view_functions[rule.endpoint](**req.view_args)
TypeError: reset_password() got an unexpected keyword argument 'token'
2018-03-30 13:30:41,968 ERROR: Exception on /reset_password/eyJ0eXAiOiJKV1QiLCJhbGciOiJIUzI1NiJ9.eyJyZXNldF9wYXNzd29yZCI6OCwiZXhwIjoxNTIyNDA2Mzg1Ljk3ODA4MTV9.2eMoIT3stwq2cGKi0Rf7D06O0qatvIdj9biev5Kc9xY [GET] [in /home/dmitry/code/python/Flask/first/venv/lib/python3.6/site-packages/flask/app.py:1560]
Traceback (most recent call last):
  File "/home/dmitry/code/python/Flask/first/venv/lib/python3.6/site-packages/flask/app.py", line 1982, in wsgi_app
    response = self.full_dispatch_request()
  File "/home/dmitry/code/python/Flask/first/venv/lib/python3.6/site-packages/flask/app.py", line 1614, in full_dispatch_request
    rv = self.handle_user_exception(e)
  File "/home/dmitry/code/python/Flask/first/venv/lib/python3.6/site-packages/flask/app.py", line 1517, in handle_user_exception
    reraise(exc_type, exc_value, tb)
  File "/home/dmitry/code/python/Flask/first/venv/lib/python3.6/site-packages/flask/_compat.py", line 33, in reraise
    raise value
  File "/home/dmitry/code/python/Flask/first/venv/lib/python3.6/site-packages/flask/app.py", line 1612, in full_dispatch_request
    rv = self.dispatch_request()
  File "/home/dmitry/code/python/Flask/first/venv/lib/python3.6/site-packages/flask/app.py", line 1598, in dispatch_request
    return self.view_functions[rule.endpoint](**req.view_args)
TypeError: reset_password() got an unexpected keyword argument 'token'
2018-03-30 13:30:43,759 ERROR: Exception on /reset_password/eyJ0eXAiOiJKV1QiLCJhbGciOiJIUzI1NiJ9.eyJyZXNldF9wYXNzd29yZCI6OCwiZXhwIjoxNTIyNDA2Mzg1Ljk3ODA4MTV9.2eMoIT3stwq2cGKi0Rf7D06O0qatvIdj9biev5Kc9xY [GET] [in /home/dmitry/code/python/Flask/first/venv/lib/python3.6/site-packages/flask/app.py:1560]
Traceback (most recent call last):
  File "/home/dmitry/code/python/Flask/first/venv/lib/python3.6/site-packages/flask/app.py", line 1982, in wsgi_app
    response = self.full_dispatch_request()
  File "/home/dmitry/code/python/Flask/first/venv/lib/python3.6/site-packages/flask/app.py", line 1614, in full_dispatch_request
    rv = self.handle_user_exception(e)
  File "/home/dmitry/code/python/Flask/first/venv/lib/python3.6/site-packages/flask/app.py", line 1517, in handle_user_exception
    reraise(exc_type, exc_value, tb)
  File "/home/dmitry/code/python/Flask/first/venv/lib/python3.6/site-packages/flask/_compat.py", line 33, in reraise
    raise value
  File "/home/dmitry/code/python/Flask/first/venv/lib/python3.6/site-packages/flask/app.py", line 1612, in full_dispatch_request
    rv = self.dispatch_request()
  File "/home/dmitry/code/python/Flask/first/venv/lib/python3.6/site-packages/flask/app.py", line 1598, in dispatch_request
    return self.view_functions[rule.endpoint](**req.view_args)
TypeError: reset_password() got an unexpected keyword argument 'token'
2018-03-30 13:30:45,577 ERROR: Exception on /reset_password/eyJ0eXAiOiJKV1QiLCJhbGciOiJIUzI1NiJ9.eyJyZXNldF9wYXNzd29yZCI6OCwiZXhwIjoxNTIyNDA2Mzg1Ljk3ODA4MTV9.2eMoIT3stwq2cGKi0Rf7D06O0qatvIdj9biev5Kc9xY [GET] [in /home/dmitry/code/python/Flask/first/venv/lib/python3.6/site-packages/flask/app.py:1560]
Traceback (most recent call last):
  File "/home/dmitry/code/python/Flask/first/venv/lib/python3.6/site-packages/flask/app.py", line 1982, in wsgi_app
    response = self.full_dispatch_request()
  File "/home/dmitry/code/python/Flask/first/venv/lib/python3.6/site-packages/flask/app.py", line 1614, in full_dispatch_request
    rv = self.handle_user_exception(e)
  File "/home/dmitry/code/python/Flask/first/venv/lib/python3.6/site-packages/flask/app.py", line 1517, in handle_user_exception
    reraise(exc_type, exc_value, tb)
  File "/home/dmitry/code/python/Flask/first/venv/lib/python3.6/site-packages/flask/_compat.py", line 33, in reraise
    raise value
  File "/home/dmitry/code/python/Flask/first/venv/lib/python3.6/site-packages/flask/app.py", line 1612, in full_dispatch_request
    rv = self.dispatch_request()
  File "/home/dmitry/code/python/Flask/first/venv/lib/python3.6/site-packages/flask/app.py", line 1598, in dispatch_request
    return self.view_functions[rule.endpoint](**req.view_args)
TypeError: reset_password() got an unexpected keyword argument 'token'
