2018-03-26 17:06:37,893 ERROR: Exception on /explore [GET] [in /home/dmitry/code/python/Flask/first/venv/lib/python3.6/site-packages/flask/app.py:1560]
Traceback (most recent call last):
  File "/home/dmitry/code/python/Flask/first/venv/lib/python3.6/site-packages/flask/app.py", line 1982, in wsgi_app
    response = self.full_dispatch_request()
  File "/home/dmitry/code/python/Flask/first/venv/lib/python3.6/site-packages/flask/app.py", line 1614, in full_dispatch_request
    rv = self.handle_user_exception(e)
  File "/home/dmitry/code/python/Flask/first/venv/lib/python3.6/site-packages/flask/app.py", line 1517, in handle_user_exception
    reraise(exc_type, exc_value, tb)
  File "/home/dmitry/code/python/Flask/first/venv/lib/python3.6/site-packages/flask/_compat.py", line 33, in reraise
    raise value
  File "/home/dmitry/code/python/Flask/first/venv/lib/python3.6/site-packages/flask/app.py", line 1612, in full_dispatch_request
    rv = self.dispatch_request()
  File "/home/dmitry/code/python/Flask/first/venv/lib/python3.6/site-packages/flask/app.py", line 1598, in dispatch_request
    return self.view_functions[rule.endpoint](**req.view_args)
  File "/home/dmitry/code/python/Flask/first/venv/lib/python3.6/site-packages/flask_login/utils.py", line 261, in decorated_view
    return func(*args, **kwargs)
  File "/home/dmitry/code/python/Flask/first/ap/routes.py", line 130, in explore
    return render_template('index.html', title='Explore', posts=posts)
  File "/home/dmitry/code/python/Flask/first/venv/lib/python3.6/site-packages/flask/templating.py", line 134, in render_template
    context, ctx.app)
  File "/home/dmitry/code/python/Flask/first/venv/lib/python3.6/site-packages/flask/templating.py", line 116, in _render
    rv = template.render(context)
  File "/home/dmitry/code/python/Flask/first/venv/lib/python3.6/site-packages/jinja2/asyncsupport.py", line 76, in render
    return original_render(self, *args, **kwargs)
  File "/home/dmitry/code/python/Flask/first/venv/lib/python3.6/site-packages/jinja2/environment.py", line 1008, in render
    return self.environment.handle_exception(exc_info, True)
  File "/home/dmitry/code/python/Flask/first/venv/lib/python3.6/site-packages/jinja2/environment.py", line 780, in handle_exception
    reraise(exc_type, exc_value, tb)
  File "/home/dmitry/code/python/Flask/first/venv/lib/python3.6/site-packages/jinja2/_compat.py", line 37, in reraise
    raise value.with_traceback(tb)
  File "/home/dmitry/code/python/Flask/first/ap/templates/index.html", line 1, in top-level template code
    {% extends "base.html" %}
  File "/home/dmitry/code/python/Flask/first/ap/templates/base.html", line 31, in top-level template code
    {% block content %}{% endblock %}
  File "/home/dmitry/code/python/Flask/first/ap/templates/index.html", line 21, in block "content"
    {% include '_post.html' %}
  File "/home/dmitry/code/python/Flask/first/ap/templates/_post.html", line 3, in top-level template code
    <td><img src="{{ post.authot.avatar(36) }}"></td>
  File "/home/dmitry/code/python/Flask/first/venv/lib/python3.6/site-packages/jinja2/environment.py", line 430, in getattr
    return getattr(obj, attribute)
jinja2.exceptions.UndefinedError: 'ap.models.Post object' has no attribute 'authot'
2018-03-26 17:06:39,765 ERROR: Exception on /explore [GET] [in /home/dmitry/code/python/Flask/first/venv/lib/python3.6/site-packages/flask/app.py:1560]
Traceback (most recent call last):
  File "/home/dmitry/code/python/Flask/first/venv/lib/python3.6/site-packages/flask/app.py", line 1982, in wsgi_app
    response = self.full_dispatch_request()
  File "/home/dmitry/code/python/Flask/first/venv/lib/python3.6/site-packages/flask/app.py", line 1614, in full_dispatch_request
    rv = self.handle_user_exception(e)
  File "/home/dmitry/code/python/Flask/first/venv/lib/python3.6/site-packages/flask/app.py", line 1517, in handle_user_exception
    reraise(exc_type, exc_value, tb)
  File "/home/dmitry/code/python/Flask/first/venv/lib/python3.6/site-packages/flask/_compat.py", line 33, in reraise
    raise value
  File "/home/dmitry/code/python/Flask/first/venv/lib/python3.6/site-packages/flask/app.py", line 1612, in full_dispatch_request
    rv = self.dispatch_request()
  File "/home/dmitry/code/python/Flask/first/venv/lib/python3.6/site-packages/flask/app.py", line 1598, in dispatch_request
    return self.view_functions[rule.endpoint](**req.view_args)
  File "/home/dmitry/code/python/Flask/first/venv/lib/python3.6/site-packages/flask_login/utils.py", line 261, in decorated_view
    return func(*args, **kwargs)
  File "/home/dmitry/code/python/Flask/first/ap/routes.py", line 130, in explore
    return render_template('index.html', title='Explore', posts=posts)
  File "/home/dmitry/code/python/Flask/first/venv/lib/python3.6/site-packages/flask/templating.py", line 134, in render_template
    context, ctx.app)
  File "/home/dmitry/code/python/Flask/first/venv/lib/python3.6/site-packages/flask/templating.py", line 116, in _render
    rv = template.render(context)
  File "/home/dmitry/code/python/Flask/first/venv/lib/python3.6/site-packages/jinja2/asyncsupport.py", line 76, in render
    return original_render(self, *args, **kwargs)
  File "/home/dmitry/code/python/Flask/first/venv/lib/python3.6/site-packages/jinja2/environment.py", line 1008, in render
    return self.environment.handle_exception(exc_info, True)
  File "/home/dmitry/code/python/Flask/first/venv/lib/python3.6/site-packages/jinja2/environment.py", line 780, in handle_exception
    reraise(exc_type, exc_value, tb)
  File "/home/dmitry/code/python/Flask/first/venv/lib/python3.6/site-packages/jinja2/_compat.py", line 37, in reraise
    raise value.with_traceback(tb)
  File "/home/dmitry/code/python/Flask/first/ap/templates/index.html", line 1, in top-level template code
    {% extends "base.html" %}
  File "/home/dmitry/code/python/Flask/first/ap/templates/base.html", line 31, in top-level template code
    {% block content %}{% endblock %}
  File "/home/dmitry/code/python/Flask/first/ap/templates/index.html", line 21, in block "content"
    {% include '_post.html' %}
  File "/home/dmitry/code/python/Flask/first/ap/templates/_post.html", line 3, in top-level template code
    <td><img src="{{ post.authot.avatar(36) }}"></td>
  File "/home/dmitry/code/python/Flask/first/venv/lib/python3.6/site-packages/jinja2/environment.py", line 430, in getattr
    return getattr(obj, attribute)
jinja2.exceptions.UndefinedError: 'ap.models.Post object' has no attribute 'authot'
2018-03-26 17:06:41,858 ERROR: Exception on /explore [GET] [in /home/dmitry/code/python/Flask/first/venv/lib/python3.6/site-packages/flask/app.py:1560]
Traceback (most recent call last):
  File "/home/dmitry/code/python/Flask/first/venv/lib/python3.6/site-packages/flask/app.py", line 1982, in wsgi_app
    response = self.full_dispatch_request()
  File "/home/dmitry/code/python/Flask/first/venv/lib/python3.6/site-packages/flask/app.py", line 1614, in full_dispatch_request
    rv = self.handle_user_exception(e)
  File "/home/dmitry/code/python/Flask/first/venv/lib/python3.6/site-packages/flask/app.py", line 1517, in handle_user_exception
    reraise(exc_type, exc_value, tb)
  File "/home/dmitry/code/python/Flask/first/venv/lib/python3.6/site-packages/flask/_compat.py", line 33, in reraise
    raise value
  File "/home/dmitry/code/python/Flask/first/venv/lib/python3.6/site-packages/flask/app.py", line 1612, in full_dispatch_request
    rv = self.dispatch_request()
  File "/home/dmitry/code/python/Flask/first/venv/lib/python3.6/site-packages/flask/app.py", line 1598, in dispatch_request
    return self.view_functions[rule.endpoint](**req.view_args)
  File "/home/dmitry/code/python/Flask/first/venv/lib/python3.6/site-packages/flask_login/utils.py", line 261, in decorated_view
    return func(*args, **kwargs)
  File "/home/dmitry/code/python/Flask/first/ap/routes.py", line 130, in explore
    return render_template('index.html', title='Explore', posts=posts)
  File "/home/dmitry/code/python/Flask/first/venv/lib/python3.6/site-packages/flask/templating.py", line 134, in render_template
    context, ctx.app)
  File "/home/dmitry/code/python/Flask/first/venv/lib/python3.6/site-packages/flask/templating.py", line 116, in _render
    rv = template.render(context)
  File "/home/dmitry/code/python/Flask/first/venv/lib/python3.6/site-packages/jinja2/asyncsupport.py", line 76, in render
    return original_render(self, *args, **kwargs)
  File "/home/dmitry/code/python/Flask/first/venv/lib/python3.6/site-packages/jinja2/environment.py", line 1008, in render
    return self.environment.handle_exception(exc_info, True)
  File "/home/dmitry/code/python/Flask/first/venv/lib/python3.6/site-packages/jinja2/environment.py", line 780, in handle_exception
    reraise(exc_type, exc_value, tb)
  File "/home/dmitry/code/python/Flask/first/venv/lib/python3.6/site-packages/jinja2/_compat.py", line 37, in reraise
    raise value.with_traceback(tb)
  File "/home/dmitry/code/python/Flask/first/ap/templates/index.html", line 1, in top-level template code
    {% extends "base.html" %}
  File "/home/dmitry/code/python/Flask/first/ap/templates/base.html", line 31, in top-level template code
    {% block content %}{% endblock %}
  File "/home/dmitry/code/python/Flask/first/ap/templates/index.html", line 21, in block "content"
    {% include '_post.html' %}
  File "/home/dmitry/code/python/Flask/first/ap/templates/_post.html", line 3, in top-level template code
    <td><img src="{{ post.authot.avatar(36) }}"></td>
  File "/home/dmitry/code/python/Flask/first/venv/lib/python3.6/site-packages/jinja2/environment.py", line 430, in getattr
    return getattr(obj, attribute)
jinja2.exceptions.UndefinedError: 'ap.models.Post object' has no attribute 'authot'
