2018-03-29 18:45:59,088 ERROR: Exception on /reset_password_request [POST] [in /home/dmitry/code/python/Flask/first/venv/lib/python3.6/site-packages/flask/app.py:1560]
Traceback (most recent call last):
  File "/home/dmitry/code/python/Flask/first/venv/lib/python3.6/site-packages/flask/app.py", line 1982, in wsgi_app
    response = self.full_dispatch_request()
  File "/home/dmitry/code/python/Flask/first/venv/lib/python3.6/site-packages/flask/app.py", line 1614, in full_dispatch_request
    rv = self.handle_user_exception(e)
  File "/home/dmitry/code/python/Flask/first/venv/lib/python3.6/site-packages/flask/app.py", line 1517, in handle_user_exception
    reraise(exc_type, exc_value, tb)
  File "/home/dmitry/code/python/Flask/first/venv/lib/python3.6/site-packages/flask/_compat.py", line 33, in reraise
    raise value
  File "/home/dmitry/code/python/Flask/first/venv/lib/python3.6/site-packages/flask/app.py", line 1612, in full_dispatch_request
    rv = self.dispatch_request()
  File "/home/dmitry/code/python/Flask/first/venv/lib/python3.6/site-packages/flask/app.py", line 1598, in dispatch_request
    return self.view_functions[rule.endpoint](**req.view_args)
  File "/home/dmitry/code/python/Flask/first/ap/routes.py", line 147, in reset_password_request
    send_password_reset_email(user)
  File "/home/dmitry/code/python/Flask/first/ap/email.py", line 13, in send_password_reset_email
    send_email('[FirstBlog] Reset Your Password', sender = app.config['ADMINS'][0], recipients = [user.email], text_body = render_template ('email/reset_password.txt', user=user, token=token), html_body = render_template('email/reset_password.html', user=user, token=token))
  File "/home/dmitry/code/python/Flask/first/venv/lib/python3.6/site-packages/flask/templating.py", line 133, in render_template
    return _render(ctx.app.jinja_env.get_or_select_template(template_name_or_list),
  File "/home/dmitry/code/python/Flask/first/venv/lib/python3.6/site-packages/jinja2/environment.py", line 869, in get_or_select_template
    return self.get_template(template_name_or_list, parent, globals)
  File "/home/dmitry/code/python/Flask/first/venv/lib/python3.6/site-packages/jinja2/environment.py", line 830, in get_template
    return self._load_template(name, self.make_globals(globals))
  File "/home/dmitry/code/python/Flask/first/venv/lib/python3.6/site-packages/jinja2/environment.py", line 804, in _load_template
    template = self.loader.load(self, name, globals)
  File "/home/dmitry/code/python/Flask/first/venv/lib/python3.6/site-packages/jinja2/loaders.py", line 113, in load
    source, filename, uptodate = self.get_source(environment, name)
  File "/home/dmitry/code/python/Flask/first/venv/lib/python3.6/site-packages/flask/templating.py", line 57, in get_source
    return self._get_source_fast(environment, template)
  File "/home/dmitry/code/python/Flask/first/venv/lib/python3.6/site-packages/flask/templating.py", line 85, in _get_source_fast
    raise TemplateNotFound(template)
jinja2.exceptions.TemplateNotFound: email/reset_password.txt
2018-03-30 12:57:54,944 INFO: Microblog startup [in /home/dmitry/code/python/Flask/first/ap/__init__.py:44]
2018-03-30 12:58:43,568 INFO: Microblog startup [in /home/dmitry/code/python/Flask/first/ap/__init__.py:44]
2018-03-30 13:30:11,676 ERROR: Exception on /reset_password/eyJ0eXAiOiJKV1QiLCJhbGciOiJIUzI1NiJ9.eyJyZXNldF9wYXNzd29yZCI6OCwiZXhwIjoxNTIyNDA2Mzg1Ljk3ODA4MTV9.2eMoIT3stwq2cGKi0Rf7D06O0qatvIdj9biev5Kc9xY [GET] [in /home/dmitry/code/python/Flask/first/venv/lib/python3.6/site-packages/flask/app.py:1560]
Traceback (most recent call last):
  File "/home/dmitry/code/python/Flask/first/venv/lib/python3.6/site-packages/flask/app.py", line 1982, in wsgi_app
    response = self.full_dispatch_request()
  File "/home/dmitry/code/python/Flask/first/venv/lib/python3.6/site-packages/flask/app.py", line 1614, in full_dispatch_request
    rv = self.handle_user_exception(e)
  File "/home/dmitry/code/python/Flask/first/venv/lib/python3.6/site-packages/flask/app.py", line 1517, in handle_user_exception
    reraise(exc_type, exc_value, tb)
  File "/home/dmitry/code/python/Flask/first/venv/lib/python3.6/site-packages/flask/_compat.py", line 33, in reraise
    raise value
  File "/home/dmitry/code/python/Flask/first/venv/lib/python3.6/site-packages/flask/app.py", line 1612, in full_dispatch_request
    rv = self.dispatch_request()
  File "/home/dmitry/code/python/Flask/first/venv/lib/python3.6/site-packages/flask/app.py", line 1598, in dispatch_request
    return self.view_functions[rule.endpoint](**req.view_args)
TypeError: reset_password() got an unexpected keyword argument 'token'
2018-03-30 13:30:13,653 ERROR: Exception on /reset_password/eyJ0eXAiOiJKV1QiLCJhbGciOiJIUzI1NiJ9.eyJyZXNldF9wYXNzd29yZCI6OCwiZXhwIjoxNTIyNDA2Mzg1Ljk3ODA4MTV9.2eMoIT3stwq2cGKi0Rf7D06O0qatvIdj9biev5Kc9xY [GET] [in /home/dmitry/code/python/Flask/first/venv/lib/python3.6/site-packages/flask/app.py:1560]
Traceback (most recent call last):
  File "/home/dmitry/code/python/Flask/first/venv/lib/python3.6/site-packages/flask/app.py", line 1982, in wsgi_app
    response = self.full_dispatch_request()
  File "/home/dmitry/code/python/Flask/first/venv/lib/python3.6/site-packages/flask/app.py", line 1614, in full_dispatch_request
    rv = self.handle_user_exception(e)
  File "/home/dmitry/code/python/Flask/first/venv/lib/python3.6/site-packages/flask/app.py", line 1517, in handle_user_exception
    reraise(exc_type, exc_value, tb)
  File "/home/dmitry/code/python/Flask/first/venv/lib/python3.6/site-packages/flask/_compat.py", line 33, in reraise
    raise value
  File "/home/dmitry/code/python/Flask/first/venv/lib/python3.6/site-packages/flask/app.py", line 1612, in full_dispatch_request
    rv = self.dispatch_request()
  File "/home/dmitry/code/python/Flask/first/venv/lib/python3.6/site-packages/flask/app.py", line 1598, in dispatch_request
    return self.view_functions[rule.endpoint](**req.view_args)
TypeError: reset_password() got an unexpected keyword argument 'token'
2018-03-30 13:30:15,530 ERROR: Exception on /reset_password/eyJ0eXAiOiJKV1QiLCJhbGciOiJIUzI1NiJ9.eyJyZXNldF9wYXNzd29yZCI6OCwiZXhwIjoxNTIyNDA2Mzg1Ljk3ODA4MTV9.2eMoIT3stwq2cGKi0Rf7D06O0qatvIdj9biev5Kc9xY [GET] [in /home/dmitry/code/python/Flask/first/venv/lib/python3.6/site-packages/flask/app.py:1560]
Traceback (most recent call last):
  File "/home/dmitry/code/python/Flask/first/venv/lib/python3.6/site-packages/flask/app.py", line 1982, in wsgi_app
    response = self.full_dispatch_request()
  File "/home/dmitry/code/python/Flask/first/venv/lib/python3.6/site-packages/flask/app.py", line 1614, in full_dispatch_request
    rv = self.handle_user_exception(e)
  File "/home/dmitry/code/python/Flask/first/venv/lib/python3.6/site-packages/flask/app.py", line 1517, in handle_user_exception
    reraise(exc_type, exc_value, tb)
  File "/home/dmitry/code/python/Flask/first/venv/lib/python3.6/site-packages/flask/_compat.py", line 33, in reraise
    raise value
  File "/home/dmitry/code/python/Flask/first/venv/lib/python3.6/site-packages/flask/app.py", line 1612, in full_dispatch_request
    rv = self.dispatch_request()
  File "/home/dmitry/code/python/Flask/first/venv/lib/python3.6/site-packages/flask/app.py", line 1598, in dispatch_request
    return self.view_functions[rule.endpoint](**req.view_args)
TypeError: reset_password() got an unexpected keyword argument 'token'
2018-03-30 13:30:17,317 ERROR: Exception on /reset_password/eyJ0eXAiOiJKV1QiLCJhbGciOiJIUzI1NiJ9.eyJyZXNldF9wYXNzd29yZCI6OCwiZXhwIjoxNTIyNDA2Mzg1Ljk3ODA4MTV9.2eMoIT3stwq2cGKi0Rf7D06O0qatvIdj9biev5Kc9xY [GET] [in /home/dmitry/code/python/Flask/first/venv/lib/python3.6/site-packages/flask/app.py:1560]
Traceback (most recent call last):
  File "/home/dmitry/code/python/Flask/first/venv/lib/python3.6/site-packages/flask/app.py", line 1982, in wsgi_app
    response = self.full_dispatch_request()
  File "/home/dmitry/code/python/Flask/first/venv/lib/python3.6/site-packages/flask/app.py", line 1614, in full_dispatch_request
    rv = self.handle_user_exception(e)
  File "/home/dmitry/code/python/Flask/first/venv/lib/python3.6/site-packages/flask/app.py", line 1517, in handle_user_exception
    reraise(exc_type, exc_value, tb)
  File "/home/dmitry/code/python/Flask/first/venv/lib/python3.6/site-packages/flask/_compat.py", line 33, in reraise
    raise value
  File "/home/dmitry/code/python/Flask/first/venv/lib/python3.6/site-packages/flask/app.py", line 1612, in full_dispatch_request
    rv = self.dispatch_request()
  File "/home/dmitry/code/python/Flask/first/venv/lib/python3.6/site-packages/flask/app.py", line 1598, in dispatch_request
    return self.view_functions[rule.endpoint](**req.view_args)
TypeError: reset_password() got an unexpected keyword argument 'token'
2018-03-30 13:30:19,122 ERROR: Exception on /reset_password/eyJ0eXAiOiJKV1QiLCJhbGciOiJIUzI1NiJ9.eyJyZXNldF9wYXNzd29yZCI6OCwiZXhwIjoxNTIyNDA2Mzg1Ljk3ODA4MTV9.2eMoIT3stwq2cGKi0Rf7D06O0qatvIdj9biev5Kc9xY [GET] [in /home/dmitry/code/python/Flask/first/venv/lib/python3.6/site-packages/flask/app.py:1560]
Traceback (most recent call last):
  File "/home/dmitry/code/python/Flask/first/venv/lib/python3.6/site-packages/flask/app.py", line 1982, in wsgi_app
    response = self.full_dispatch_request()
  File "/home/dmitry/code/python/Flask/first/venv/lib/python3.6/site-packages/flask/app.py", line 1614, in full_dispatch_request
    rv = self.handle_user_exception(e)
  File "/home/dmitry/code/python/Flask/first/venv/lib/python3.6/site-packages/flask/app.py", line 1517, in handle_user_exception
    reraise(exc_type, exc_value, tb)
  File "/home/dmitry/code/python/Flask/first/venv/lib/python3.6/site-packages/flask/_compat.py", line 33, in reraise
    raise value
  File "/home/dmitry/code/python/Flask/first/venv/lib/python3.6/site-packages/flask/app.py", line 1612, in full_dispatch_request
    rv = self.dispatch_request()
  File "/home/dmitry/code/python/Flask/first/venv/lib/python3.6/site-packages/flask/app.py", line 1598, in dispatch_request
    return self.view_functions[rule.endpoint](**req.view_args)
TypeError: reset_password() got an unexpected keyword argument 'token'
